<?xml version="1.0" ?>
<!--
  This is not a standalone urdf for kobuki. It simply defines the 'kobuki' tag that can
  be incorporated by other urdf files (e.g. turtlebot).

  See kobuki_standalone.urdf.xacro for a standalone urdf to be tested with
      kobuki_description/launch/view_model.launch
 -->
<robot name="kobuki" xmlns:xacro="http://ros.org/wiki/xacro">
  <xacro:include filename="$(find kobuki_description)/urdf/common_properties.urdf.xacro"/>
  <xacro:include filename="$(find kobuki_description)/urdf/kobuki_gazebo.urdf.xacro"/>

  <!-- Kobuki -->
  <xacro:macro name="kobuki">
    <link name="base_footprint"/>
    <!--
       Base link is set at the bottom of the base mould.
       This is done to be compatible with the way base link
       was configured for turtlebot 1. Refer to

       https://github.com/turtlebot/turtlebot/issues/40

       To put the base link at the more oft used wheel
       axis, set the z-distance from the base_footprint
       to 0.352.
      -->
    <joint name="base_joint" type="fixed">
      <origin xyz="0 0 0.0102" rpy="0 0 0" />
      <parent link="base_footprint"/>
      <child link="base_link" />
    </joint>


    <link name='leftScoop'>
      <pose frame=''>-0 -0 0 0 -0 0</pose>
      <inertial>
<mass value="0.1"/>
        <inertia ixx="0.166667" ixy="0.0" ixz="0.0"
                 iyy="0.166667" iyz="0.0"
                 izz="0.166667" />
      </inertial>
        <pose frame=''>0 0 0 0 -0 0</pose>

      <gravity>1</gravity>
      <self_collide>0</self_collide>
      <kinematic>0</kinematic>
      <visual name='visual'>

        <pose frame=''>0 0 0 0 -0 0</pose>
        <geometry>
          <box size="0.5 0.1 0.1"/>
        </geometry>

        <cast_shadows>1</cast_shadows>
        <transparency>0</transparency>
      </visual>
      <collision name='collision'>
        <laser_retro>0</laser_retro>
        <max_contacts>10</max_contacts>
        <pose frame=''>0 0 0 0 -0 0</pose>
        <geometry>
<box size="0.5 0.1 0.1"/>
        </geometry>
        <surface>
          <friction>
            <ode>
              <mu>1</mu>
              <mu2>1</mu2>
              <fdir1>0 0 0</fdir1>
              <slip1>0</slip1>
              <slip2>0</slip2>
            </ode>
            <torsional>
              <coefficient>1</coefficient>
              <patch_radius>0</patch_radius>
              <surface_radius>0</surface_radius>
              <use_patch_radius>1</use_patch_radius>
              <ode>
                <slip>0</slip>
              </ode>
            </torsional>
          </friction>
          <bounce>
            <restitution_coefficient>0</restitution_coefficient>
            <threshold>1e+06</threshold>
          </bounce>
          <contact>
            <collide_without_contact>0</collide_without_contact>
            <collide_without_contact_bitmask>1</collide_without_contact_bitmask>
            <collide_bitmask>1</collide_bitmask>
            <ode>
              <soft_cfm>0</soft_cfm>
              <soft_erp>0.2</soft_erp>
              <kp>1e+13</kp>
              <kd>1</kd>
              <max_vel>0.01</max_vel>
              <min_depth>0</min_depth>
            </ode>
            <bullet>
              <split_impulse>1</split_impulse>
              <split_impulse_penetration_threshold>-0.01</split_impulse_penetration_threshold>
              <soft_cfm>0</soft_cfm>
              <soft_erp>0.2</soft_erp>
              <kp>1e+13</kp>
              <kd>1</kd>
            </bullet>
          </contact>
        </surface>
      </collision>
    </link>

    <joint name="base_joint2" type="fixed">
      <origin xyz="0.2 0.2 0.1" rpy="0 0 -0.2" />
      <parent link="base_footprint"/>
      <child link="leftScoop" />
    </joint>




    <link name='middleScoop'>
      <pose frame=''>-0 -0 0 0 -0 0</pose>
      <inertial>
<mass value="0.1"/>
        <inertia ixx="0.166667" ixy="0.0" ixz="0.0"
                 iyy="0.166667" iyz="0.0"
                 izz="0.166667" />
      </inertial>
        <pose frame=''>0 0 0 0 -0 0</pose>

      <gravity>1</gravity>
      <self_collide>0</self_collide>
      <kinematic>0</kinematic>
      <visual name='visual'>
        <pose frame=''>0 0 0 0 -0 0</pose>
        <geometry>
          <box size="0.2 0.1 0.1"/>
        </geometry>

        <cast_shadows>1</cast_shadows>
        <transparency>0</transparency>
      </visual>
      <collision name='collision'>
        <laser_retro>0</laser_retro>
        <max_contacts>10</max_contacts>
        <pose frame=''>0 0 0 0 -0 0</pose>
        <geometry>
<box size="0.2 0.1 0.1"/>
        </geometry>
        <surface>
          <friction>
            <ode>
              <mu>1</mu>
              <mu2>1</mu2>
              <fdir1>0 0 0</fdir1>
              <slip1>0</slip1>
              <slip2>0</slip2>
            </ode>
            <torsional>
              <coefficient>1</coefficient>
              <patch_radius>0</patch_radius>
              <surface_radius>0</surface_radius>
              <use_patch_radius>1</use_patch_radius>
              <ode>
                <slip>0</slip>
              </ode>
            </torsional>
          </friction>
          <bounce>
            <restitution_coefficient>0</restitution_coefficient>
            <threshold>1e+06</threshold>
          </bounce>
          <contact>
            <collide_without_contact>0</collide_without_contact>
            <collide_without_contact_bitmask>1</collide_without_contact_bitmask>
            <collide_bitmask>1</collide_bitmask>
            <ode>
              <soft_cfm>0</soft_cfm>
              <soft_erp>0.2</soft_erp>
              <kp>1e+13</kp>
              <kd>1</kd>
              <max_vel>0.01</max_vel>
              <min_depth>0</min_depth>
            </ode>
            <bullet>
              <split_impulse>1</split_impulse>
              <split_impulse_penetration_threshold>-0.01</split_impulse_penetration_threshold>
              <soft_cfm>0</soft_cfm>
              <soft_erp>0.2</soft_erp>
              <kp>1e+13</kp>
              <kd>1</kd>
            </bullet>
          </contact>
        </surface>
      </collision>
    </link>

    <joint name="base_joint3" type="fixed">
      <origin xyz="0.23 0.0 0.1" rpy="0 0 1.571" />
      <parent link="base_footprint"/>
      <child link="middleScoop" />
    </joint>



<link name='rightScoop'>
      <pose frame=''>-0 -0 0 0 -0 0</pose>
      <inertial>
<mass value="0.1"/>
        <inertia ixx="0.166667" ixy="0.0" ixz="0.0"
                 iyy="0.166667" iyz="0.0"
                 izz="0.166667" />
      </inertial>
        <pose frame=''>0 0 0 0 -0 0</pose>

      <gravity>1</gravity>
      <self_collide>0</self_collide>
      <kinematic>0</kinematic>
      <visual name='visual'>
        <pose frame=''>0 0 0 0 -0 0</pose>
        <geometry>
          <box size="0.5 0.1 0.1"/>
        </geometry>

        <cast_shadows>1</cast_shadows>
        <transparency>0</transparency>
      </visual>
      <collision name='collision'>
        <laser_retro>0</laser_retro>
        <max_contacts>10</max_contacts>
        <pose frame=''>0 0 0 0 -0 0</pose>
        <geometry>
<box size="0.5 0.1 0.1"/>
        </geometry>
        <surface>
          <friction>
            <ode>
              <mu>1</mu>
              <mu2>1</mu2>
              <fdir1>0 0 0</fdir1>
              <slip1>0</slip1>
              <slip2>0</slip2>
            </ode>
            <torsional>
              <coefficient>1</coefficient>
              <patch_radius>0</patch_radius>
              <surface_radius>0</surface_radius>
              <use_patch_radius>1</use_patch_radius>
              <ode>
                <slip>0</slip>
              </ode>
            </torsional>
          </friction>
          <bounce>
            <restitution_coefficient>0</restitution_coefficient>
            <threshold>1e+06</threshold>
          </bounce>
          <contact>
            <collide_without_contact>0</collide_without_contact>
            <collide_without_contact_bitmask>1</collide_without_contact_bitmask>
            <collide_bitmask>1</collide_bitmask>
            <ode>
              <soft_cfm>0</soft_cfm>
              <soft_erp>0.2</soft_erp>
              <kp>1e+13</kp>
              <kd>1</kd>
              <max_vel>0.01</max_vel>
              <min_depth>0</min_depth>
            </ode>
            <bullet>
              <split_impulse>1</split_impulse>
              <split_impulse_penetration_threshold>-0.01</split_impulse_penetration_threshold>
              <soft_cfm>0</soft_cfm>
              <soft_erp>0.2</soft_erp>
              <kp>1e+13</kp>
              <kd>1</kd>
            </bullet>
          </contact>
        </surface>
      </collision>
    </link>

    <joint name="base_joint4" type="fixed">
      <origin xyz="0.2 -0.2 0.1" rpy="0 0 0.2" />
      <parent link="base_footprint"/>
      <child link="rightScoop" />
    </joint>

    <link name="base_link">
      <visual>
        <geometry>
          <!-- new mesh -->
          <mesh filename="package://kobuki_description/meshes/main_body.dae" />
        </geometry>
        <origin xyz="0.001 0 0.05199" rpy="0 0 0"/>
      </visual>
      <collision name="base">
        <geometry>
          <cylinder length="0.10938" radius="0.178"/>
        </geometry>
        <origin xyz="0.0 0 0.05949" rpy="0 0 0"/>
      </collision>
      <inertial>
        <!-- COM experimentally determined -->
        <origin xyz="0.01 0 0"/>
        <mass value="2.4"/> <!-- 2.4/2.6 kg for small/big battery pack -->
        <!-- Kobuki's inertia tensor is approximated by a cylinder with homogeneous mass distribution
             More details: http://en.wikipedia.org/wiki/List_of_moment_of_inertia_tensors
             m = 2.4 kg; h = 0.09 m; r = 0.175 m
             ixx = 1/12 * m * (3 * r^2 + h^2)
             iyy = 1/12 * m * (3 * r^2 + h^2)
             izz = 1/2 * m * r^2
          -->
        <inertia ixx="0.019995" ixy="0.0" ixz="0.0"
                 iyy="0.019995" iyz="0.0"
                 izz="0.03675" />
      </inertial>
    </link>

    <joint name="wheel_left_joint" type="continuous">
      <parent link="base_link"/>
      <child link="wheel_left_link"/>
      <origin xyz="0.00 ${0.23/2} 0.0250" rpy="${-M_PI/2} 0 0"/>
      <axis xyz="0 0 1"/>
    </joint>
    <link name="wheel_left_link">
      <visual>
        <geometry>
          <mesh filename="package://kobuki_description/meshes/wheel.dae"/>
        </geometry>
        <origin xyz="0 0 0" rpy="0 0 0"/>
      </visual>
      <collision>
        <geometry>
          <cylinder length="0.0206" radius="0.0352"/>
        </geometry>
        <origin rpy="0 0 0" xyz="0 0 0"/>
      </collision>
      <inertial>
        <mass value="0.01" />
        <origin xyz="0 0 0" />
        <inertia ixx="0.001" ixy="0.0" ixz="0.0"
                 iyy="0.001" iyz="0.0"
                 izz="0.001" />
      </inertial>
    </link>

    <joint name="wheel_right_joint" type="continuous">
      <parent link="base_link"/>
      <child link="wheel_right_link"/>
      <origin xyz="0.00 -${0.23/2} 0.0250" rpy="${-M_PI/2} 0 0"/>
      <axis xyz="0 0 1"/>
    </joint>
    <link name="wheel_right_link">
      <visual>
        <geometry>
          <mesh filename="package://kobuki_description/meshes/wheel.dae"/>
        </geometry>
        <origin xyz="0 0 0" rpy="0 0 0"/>
      </visual>
      <collision>
        <geometry>
          <cylinder length="0.0206" radius="0.0350"/>
        </geometry>
        <origin rpy="0 0 0" xyz="0 0 0"/>
      </collision>
      <inertial>
        <mass value="0.01" />
        <origin xyz="0 0 0" />
        <inertia ixx="0.001" ixy="0.0" ixz="0.0"
                 iyy="0.001" iyz="0.0"
                 izz="0.001" />
      </inertial>
    </link>

    <joint name="caster_front_joint" type="fixed">
      <parent link="base_link"/>
      <child link="caster_front_link"/>
      <origin xyz="0.115 0.0 0.007" rpy="${-M_PI/2} 0 0"/>
    </joint>
    <link name="caster_front_link">
      <collision>
        <geometry>
          <cylinder length="0.0176" radius="0.017"/>
        </geometry>
        <origin rpy="0 0 0" xyz="0 0 0"/>
      </collision>
      <inertial>
        <mass value="0.01" />
        <origin xyz="0 0 0" />
        <inertia ixx="0.001" ixy="0.0" ixz="0.0"
                 iyy="0.001" iyz="0.0"
                 izz="0.001" />
      </inertial>
    </link>

    <joint name="caster_back_joint" type="fixed">
      <parent link="base_link"/>
      <child link="caster_back_link"/>
      <origin xyz="-0.135 0.0 0.009" rpy="${-M_PI/2} 0 0"/>
    </joint>
    <link name="caster_back_link">
      <collision>
        <geometry>
          <cylinder length="0.0176" radius="0.017"/>
        </geometry>
        <origin rpy="0 0 0" xyz="0 0 0"/>
      </collision>
      <inertial>
        <mass value="0.01" />
        <origin xyz="0 0 0" />
        <inertia ixx="0.001" ixy="0.0" ixz="0.0"
                 iyy="0.001" iyz="0.0"
                 izz="0.001" />
      </inertial>
    </link>

    <!-- Kobuki's sensors -->
    <joint name="gyro_joint" type="fixed">
      <axis xyz="0 1 0"/>
      <origin xyz="0.056 0.062 0.0202" rpy="0 0 0"/>
      <parent link="base_link"/>
      <child link="gyro_link"/>
    </joint>
    <link name="gyro_link">
      <inertial>
        <mass value="0.001"/>
        <origin xyz="0 0 0" rpy="0 0 0"/>
        <inertia ixx="0.0001" ixy="0" ixz="0"
                 iyy="0.000001" iyz="0"
                 izz="0.0001"/>
      </inertial>
    </link>

    <joint name="cliff_sensor_left_joint" type="fixed">
      <origin xyz="0.08734 0.13601 0.0214" rpy="0 ${M_PI/2} 0" />
      <parent link="base_link"/>
      <child link="cliff_sensor_left_link" />
    </joint>
    <link name="cliff_sensor_left_link">
      <inertial>
        <mass value="0.0001" />
        <origin xyz="0 0 0" />
        <inertia ixx="0.0001" ixy="0.0" ixz="0.0"
                 iyy="0.0001" iyz="0.0"
                 izz="0.0001" />
      </inertial>
    </link>

    <joint name="cliff_sensor_right_joint" type="fixed">
      <origin xyz="0.085 -0.13601 0.0214" rpy="0 ${M_PI/2} 0" />
      <parent link="base_link"/>
      <child link="cliff_sensor_right_link" />
    </joint>
    <link name="cliff_sensor_right_link">
      <inertial>
        <mass value="0.0001" />
        <origin xyz="0 0 0" />
        <inertia ixx="0.0001" ixy="0.0" ixz="0.0"
                 iyy="0.0001" iyz="0.0"
                 izz="0.0001" />
      </inertial>
    </link>

    <joint name="cliff_sensor_front_joint" type="fixed">
      <origin xyz="0.156 0.00 0.0214" rpy="0 ${M_PI/2} 0" />
      <parent link="base_link"/>
      <child link="cliff_sensor_front_link" />
    </joint>
    <link name="cliff_sensor_front_link">
      <inertial>
        <mass value="0.0001" />
        <origin xyz="0 0 0" />
        <inertia ixx="0.0001" ixy="0.0" ixz="0.0"
                 iyy="0.0001" iyz="0.0"
                 izz="0.0001" />
      </inertial>
    </link>

    <!-- Kobuki Gazebo simulation details -->
    <kobuki_sim/>

  </xacro:macro>
</robot>
